Workbook

Sheet Employee Data
A1: Unreal Consulting — Employee Dataset (Solved Workbook)
A2: Employee ID | B2: Full Name | C2: Department | D2: Job Level | E2: Location | F2: Work Mode | G2: Gender | H2: Age | I2: Tenure (Years) | J2: Salary (£) | K2: Bonus % | L2: Performance Rating | M2: Training Hours | N2: Last Promotion | O2: Voluntary Leaver | P2: Manager ID
A3: UC-0001 | B3: Emre Tessema | C3: Technology | D3: Director | E3: London | F3: Hybrid | G3: Male | H3: 50 | I3: 7.1 | J3: 149500 | K3: 21.2 | L3: 3 | M3: 22 | N3: 2022 | O3: No | P3: UC-0000
A4: UC-0002 | B4: Indigo Turner | C4: Technology | D4: Director | E4: London | F4: Hybrid | G4: Non-binary | H4: 49 | I4: 11.5 | J4: 137000 | K4: 19.2 | L4: 3 | M4: 13 | N4: 2021 | O4: No | P4: UC-0000
A5: UC-0003 | B5: Fatima Cross | C5: Technology | D5: Director | E5: London | F5: Office | G5: Female | H5: 42 | I5: 11.2 | J5: 139500 | K5: 21.4 | L5: 3 | M5: 15 | N5: 2024 | O5: No | P5: UC-0000
A6: UC-0004 | B6: Elspeth Campbell | C6: Technology | D6: Lead | E6: London | F6: Hybrid | G6: Female | H6: 30 | I6: 9.4 | J6: 102000 | K6: 18.6 | L6: 3 | M6: 14 | N6: 2020 | O6: No | P6: UC-0001
A7: UC-0005 | B7: Brigitte Vargas | C7: Technology | D7: Lead | E7: Edinburgh | F7: Hybrid | G7: Female | H7: 42 | I7: 5.3 | J7: 104500 | K7: 16.2 | L7: 4 | M7: 22 | N7: 2021 | O7: Yes | P7: UC-0001
A8: UC-0006 | B8: Michael Finlay | C8: Technology | D8: Lead | E8: London | F8: Office | G8: Male | H8: 35 | I8: 7.6 | J8: 108500 | K8: 14.9 | L8: 3 | M8: 18 | N8: 2023 | O8: No | P8: UC-0001
A9: UC-0007 | B9: Victor Ahmed | C9: Technology | D9: Lead | E9: London | F9: Hybrid | G9: Male | H9: 42 | I9: 8.8 | J9: 123500 | K9: 18.6 | L9: 4 | M9: 16 | N9: 2023 | O9: No | P9: UC-0001
A10: UC-0008 | B10: Yusuf Bradley | C10: Technology | D10: Lead | E10: London | F10: Remote | G10: Male | H10: 29 | I10: 6 | J10: 123000 | K10: 19.1 | L10: 5 | M10: 17 | N10: 2024 | O10: No | P10: UC-0001
A11: UC-0009 | B11: Cian Osei | C11: Technology | D11: Lead | E11: London | F11: Office | G11: Male | H11: 36 | I11: 9.6 | J11: 117500 | K11: 18.1 | L11: 4 | M11: 18 | N11: 2023 | O11: No | P11: UC-0001
A12: UC-0010 | B12: Fatima Bergstrom | C12: Technology | D12: Lead | E12: London | F12: Hybrid | G12: Female | H12: 42 | I12: 6.9 | J12: 111000 | K12: 19.5 | L12: 5 | M12: 15 | N12: 2022 | O12: No | P12: UC-0001
A13: UC-0011 | B13: Chioma Ahmed | C13: Technology | D13: Senior | E13: London | F13: Remote | G13: Female | H13: 36 | I13: 6.5 | J13: 90000 | K13: 13.8 | L13: 5 | M13: 34 | N13: 2021 | O13: Yes | P13: UC-0004
A14: UC-0012 | B14: Hugo Dubois | C14: Technology | D14: Senior | E14: London | F14: Hybrid | G14: Male | H14: 34 | I14: 7.1 | J14: 83500 | K14: 14.6 | L14: 3 | M14: 23 | N14: 2021 | O14: No | P14: UC-0004
... A40: UC-0038 | B40: Andrei Tessema | C40: Technology | D40: Mid | E40: London | F40: Remote | G40: Male | H40: 25 | I40: 2.3 | J40: 56500 | K40: 8.6 | L40: 3 | M40: 25 | N40: 2024 | O40: No | P40: UC-0011
A41: UC-0039 | B41: Bence Al-Hassan | C41: Technology | D41: Junior | E41: London | F41: Hybrid | G41: Male | H41: 27 | I41: 2 | J41: 41500 | K41: 7.4 | L41: 4 | M41: 45 | O41: Yes | P41: UC-0023
A42: UC-0040 | B42: Anna Nkosi | C42: Technology | D42: Junior | E42: London | F42: Hybrid | G42: Female | H42: 23 | I42: 2.7 | J42: 40500 | K42: 5.1 | L42: 4 | M42: 44 | O42: Yes | P42: UC-0023
A43: UC-0041 | B43: Lena Rao | C43: Technology | D43: Junior | E43: London | F43: Remote | G43: Female | H43: 24 | I43: 1.2 | J43: 30000 | K43: 2.7 | L43: 2 | M43: 28 | O43: No | P43: UC-0023
A44: UC-0042 | B44: Elena Lin | C44: Technology | D44: Junior | E44: London | F44: Remote | G44: Female | H44: 24 | I44: 2.2 | J44: 35000 | K44: 6 | L44: 3 | M44: 27 | O44: No | P44: UC-0023
A45: UC-0043 | B45: Tunde Alderton | C45: Technology | D45: Junior | E45: London | F45: Hybrid | G45: Male | H45: 22 | I45: 1.8 | J45: 43000 | K45: 5.2 | L45: 4 | M45: 38 | N45: 2023 | O45: Yes | P45: UC-0023
A46: UC-0044 | B46: Olamide Bergstrom | C46: Technology | D46: Junior | E46: Manchester | F46: Office | G46: Female | H46: 24 | I46: 1.3 | J46: 36500 | K46: 8.4 | L46: 4 | M46: 30 | O46: Yes | P46: UC-0023
A47: UC-0045 | B47: Rosalyn Mansouri | C47: Technology | D47: Junior | E47: Manchester | F47: Remote | G47: Female | H47: 22 | I47: 0.3 | J47: 34500 | K47: 2.6 | L47: 3 | M47: 36 | O47: No | P47: UC-0023
A48: UC-0046 | B48: Raphael Ojo | C48: Technology | D48: Junior | E48: Manchester | F48: Hybrid | G48: Male | H48: 23 | I48: 0.3 | J48: 35000 | K48: 4.8 | L48: 3 | M48: 34 | O48: No | P48: UC-0023
A49: UC-0047 | B49: Raphael Reynolds | C49: Technology | D49: Junior | E49: London | F49: Remote | G49: Male | H49: 23 | I49: 2.6 | J49: 40000 | K49: 2.5 | L49: 3 | M49: 30 | N49: 2023 | O49: No | P49: UC-0023
A50: UC-0048 | B50: Niall Dubois | C50: Technology | D50: Junior | E50: London | F50: Hybrid | G50: Male | H50: 24 | I50: 0.3 | J50: 42000 | K50: 5.3 | L50: 4 | M50: 45 | O50: No | P50: UC-0023
A51: UC-0049 | B51: Connor Evans | C51: Technology | D51: Junior | E51: London | F51: Hybrid | G51: Male | H51: 24 | I51: 2.2 | J51: 42500 | K51: 6.8 | L51: 4 | M51: 26 | N51: 2022 | O51: Yes | P51: UC-0023
A52: UC-0050 | B52: Helene Reid | C52: Technology | D52: Junior | E52: London | F52: Office | G52: Female | H52: 27 | I52: 2.5 | J52: 38500 | K52: 6.5 | L52: 4 | M52: 33 | O52: No | P52: UC-0023
A53: UC-0051 | B53: Darius Mensah | C53: Strategy | D53: Director | E53: Edinburgh | F53: Hybrid | G53: Male | H53: 49 | I53: 9.9 | J53: 145500 | K53: 20.4 | L53: 3 | M53: 9 | N53: 2024 | O53: No | P53: UC-0000
A54: UC-0052 | B54: Layla Hassan | C54: Strategy | D54: Director | E54: Edinburgh | F54: Office | G54: Female | H54: 48 | I54: 10 | J54: 144000 | K54: 20.1 | L54: 4 | M54: 13 | N54: 2021 | O54: No | P54: UC-0000
A55: UC-0053 | B55: Zoe Okafor | C55: Strategy | D55: Lead | E55: Edinburgh | F55: Hybrid | G55: Female | H55: 42 | I55: 8.5 | J55: 99500 | K55: 17 | L55: 3 | M55: 8 | N55: 2020 | O55: No | P55: UC-0051
A56: UC-0054 | B56: Nathan Wright | C56: Strategy | D56: Lead | E56: London | F56: Office | G56: Male | H56: 43 | I56: 8 | J56: 115000 | K56: 18.7 | L56: 4 | M56: 4 | N56: 2022 | O56: No | P56: UC-0051
A57: UC-0055 | B57: Cecilia Mansouri | C57: Strategy | D57: Lead | E57: Manchester | F57: Hybrid | G57: Female | H57: 41 | I57: 11.5 | J57: 94500 | K57: 16.7 | L57: 3 | M57: 19 | N57: 2023 | O57: No | P57: UC-0051
A58: UC-0056 | B58: Seun Draper | C58: Strategy | D58: Lead | E58: London | F58: Remote | G58: Male | H58: 36 | I58: 7.7 | J58: 113500 | K58: 18.4 | L58: 4 | M58: 12 | N58: 2023 | O58: No | P58: UC-0051
A59: UC-0057 | B59: Rebecca MacDonald | C59: Strategy | D59: Lead | E59: London | F59: Office | G59: Female | H59: 48 | I59: 12.4 | J59: 94000 | K59: 12.9 | L59: 2 | M59: 14 | N59: 2021 | O59: No | P59: UC-0051
A60: UC-0058 | B60: Abdou Nwosu | C60: Strategy | D60: Senior | E60: London | F60: Hybrid | G60: Male | H60: 35 | I60: 7.8 | J60: 86000 | K60: 11.6 | L60: 3 | M60: 7 | N60: 2022 | O60: No | P60: UC-0053
A61: UC-0059 | B61: Sasha Anand | C61: Strategy | D61: Senior | E61: Edinburgh | F61: Hybrid | G61: Non-binary | H61: 34 | I61: 7.9 | J61: 88000 | K61: 12.7 | L61: 4 | M61: 17 | N61: 2023 | O61: No | P61: UC-0053
A62: UC-0060 | B62: Hamid Santos | C62: Strategy | D62: Senior | E62: London | F62: Remote | G62: Male | H62: 27 | I62: 6 | J62: 79000 | K62: 11.6 | L62: 3 | M62: 8 | N62: 2023 | O62: No | P62: UC-0053
A63: UC-0061 | B63: Isabel Vargas | C63: Strategy | D63: Senior | E63: London | F63: Hybrid | G63: Female | H63: 25 | I63: 0.9 | J63: 62500 | K63: 7.3 | L63: 2 | M63: 8 | N63: 2024 | O63: No | P63: UC-0053
A64: UC-0062 | B64: Adebayo Ojo | C64: Strategy | D64: Senior | E64: Manchester | F64: Hybrid | G64: Male | H64: 36 | I64: 2.8 | J64: 77500 | K64: 10.3 | L64: 3 | M64: 18 | N64: 2023 | O64: No | P64: UC-0053
... A82: UC-0080 | B82: Natalie Eriksson | C82: Strategy | D82: Mid | E82: London | F82: Remote | G82: Female | H82: 32 | I82: 2.1 | J82: 48000 | K82: 6.2 | L82: 3 | M82: 28 | N82: 2024 | O82: No | P82: UC-0058
...

Sheet Ch3 — Counting
A1: Chapter 3 — Counting & Headcount
A2: Formulas reference the 'Employee Data' sheet in this workbook.
A4: COUNT FAMILY
A5: Total employees (COUNTA) | B5: =COUNTA('Employee Data'!B3:B202) -> 200 | C5: → 200
A6: Employees with salary on record (COUNT) | B6: =COUNT('Employee Data'!J3:J202) -> 200 | C6: → 200 (data quality check)
A7: Employees never promoted (COUNTBLANK) | B7: =COUNTBLANK('Employee Data'!N3:N202) -> 59 | C7: → ~59 (Juniors too new + some Mids)
A9: COUNTIF — Single Condition
A10: Headcount: Technology | B10: =COUNTIF('Employee Data'!C3:C202,"Technology") -> 50
A11: Headcount: Strategy | B11: =COUNTIF('Employee Data'!C3:C202,"Strategy") -> 40
A12: Headcount: Finance | B12: =COUNTIF('Employee Data'!C3:C202,"Finance") -> 38
A13: Headcount: Operations | B13: =COUNTIF('Employee Data'!C3:C202,"Operations") -> 45
A14: Headcount: People & Culture | B14: =COUNTIF('Employee Data'!C3:C202,"People & Culture") -> 27
A15: Senior-level employees | B15: =COUNTIF('Employee Data'!D3:D202,"Senior") -> 45
A16: Remote workers | B16: =COUNTIF('Employee Data'!F3:F202,"Remote") -> 72
A17: Hybrid workers | B17: =COUNTIF('Employee Data'!F3:F202,"Hybrid") -> 87
A18: Employees rated 4 or above (>=4) | B18: =COUNTIF('Employee Data'!L3:L202,">=4") -> 81
A19: Voluntary leavers (total) | B19: =COUNTIF('Employee Data'!O3:O202,"Yes") -> 31
A21: COUNTIFS — Multiple Conditions
A22: Technology leavers | B22: =COUNTIFS('Employee Data'!C3:C202,"Technology",'Employee Data'!O3:O202,"Yes") -> 13 | C22: → 13 — the attrition story
A23: Female Senior employees | B23: =COUNTIFS('Employee Data'!G3:G202,"Female",'Employee Data'!D3:D202,"Senior") -> 16
A24: Male Leads in London | B24: =COUNTIFS('Employee Data'!G3:G202,"Male",'Employee Data'!D3:D202,"Lead",'Employee Data'!E3:E202,"London") -> 7
A25: High performers who left (≥4 AND leaver) | B25: =COUNTIFS('Employee Data'!L3:L202,">=4",'Employee Data'!O3:O202,"Yes") -> 24 | C25: → majority of leavers — alarming
A27: Try It Yourself — Answers
A28: Q1: Total headcount | B28: =COUNTA('Employee Data'!B3:B202) -> 200
A29: Q2: Missing salaries? | B29: =COUNTBLANK('Employee Data'!J3:J202) -> 0 | C29: → 0 (none missing)
A30: Q3: Office workers in Manchester | B30: =COUNTIFS('Employee Data'!E3:E202,"Manchester",'Employee Data'!F3:F202,"Office") -> 9
A31: Q4: Junior leavers | B31: =COUNTIFS('Employee Data'!D3:D202,"Junior",'Employee Data'!O3:O202,"Yes") -> 11
A32: Q5: Remote AND rated 5 | B32: =COUNTIFS('Employee Data'!F3:F202,"Remote",'Employee Data'!L3:L202,5) -> 10

Sheet Ch4 — Salary & Cost
A1: Chapter 4 — Salary Cost & SUMIF
A2: SUM, SUMIF, SUMIFS, SUMPRODUCT.
A4: TOTAL SALARY
A5: Total salary bill | B5: =SUM('Employee Data'!J3:J202) -> 12504000
A6: Total bonus cost | B6: =SUMPRODUCT('Employee Data'!J3:J202,'Employee Data'!K3:K202/100) -> 1472305 | C6: Multiply each salary × bonus%, sum all
A7: Total cash compensation | B7: =SUM('Employee Data'!J3:J202)+SUMPRODUCT('Employee Data'!J3:J202,'Employee Data'!K3:K202/100) -> 13976305
A8: Leavers' combined salary | B8: =SUMIF('Employee Data'!O3:O202,"Yes",'Employee Data'!J3:J202) -> 1908500 | C8: Cost-of-attrition starting point
A10: SUMIF — Department Salary Costs
A11: Total salary — Technology | B11: =SUMIF('Employee Data'!C3:C202,"Technology",'Employee Data'!J3:J202) -> 3586500
A12: Total salary — Strategy | B12: =SUMIF('Employee Data'!C3:C202,"Strategy",'Employee Data'!J3:J202) -> 2679000
A13: Total salary — Finance | B13: =SUMIF('Employee Data'!C3:C202,"Finance",'Employee Data'!J3:J202) -> 2365000
A14: Total salary — Operations | B14: =SUMIF('Employee Data'!C3:C202,"Operations",'Employee Data'!J3:J202) -> 2515000
A15: Total salary — People & Culture | B15: =SUMIF('Employee Data'!C3:C202,"People & Culture",'Employee Data'!J3:J202) -> 1358500
A17: SUMIF — Other Cuts
A18: Total salary — Senior level | B18: =SUMIF('Employee Data'!D3:D202,"Senior",'Employee Data'!J3:J202) -> 3671500
A19: Total salary — Remote workers | B19: =SUMIF('Employee Data'!F3:F202,"Remote",'Employee Data'!J3:J202) -> 4262500
A21: SUMIFS — Multiple Conditions
A22: Salary — Female Seniors | B22: =SUMIFS('Employee Data'!J3:J202,'Employee Data'!G3:G202,"Female",'Employee Data'!D3:D202,"Senior") -> 1256000
A23: Salary — Hybrid, Technology dept | B23: =SUMIFS('Employee Data'!J3:J202,'Employee Data'!F3:F202,"Hybrid",'Employee Data'!C3:C202,"Technology") -> 1636000
A24: Bonus cost — Performance ≥4 (SUMPRODUCT) | B24: =SUMPRODUCT(('Employee Data'!L3:L202>=4)*'Employee Data'!J3:J202*'Employee Data'!K3:K202/100) -> 733994 | C24: Array-style SUMPRODUCT — no helper column needed
A25: Tech leavers' total salary | B25: =SUMIFS('Employee Data'!J3:J202,'Employee Data'!C3:C202,"Technology",'Employee Data'!O3:O202,"Yes") -> 820000
A27: AVERAGE COST
A28: Average salary — all staff | B28: =AVERAGE('Employee Data'!J3:J202) -> 62520
A29: Average salary — Technology | B29: =AVERAGEIF('Employee Data'!C3:C202,"Technology",'Employee Data'!J3:J202) -> 71730
A30: Average salary — Operations | B30: =AVERAGEIF('Employee Data'!C3:C202,"Operations",'Employee Data'!J3:J202) -> 55888.889

Sheet Ch5 — Pay Equity
A1: Chapter 5 — Averages & Pay Equity
A2: Mean, Median, Mode — and the gender pay gap.
A4: MEAN, MEDIAN, MODE
A5: Mean salary | B5: =AVERAGE('Employee Data'!J3:J202) -> 62520
A6: Median salary | B6: =MEDIAN('Employee Data'!J3:J202) -> 54750 | C6: Compare: median lower due to high-earner skew
A7: Mean–Median gap | B7: =AVERAGE('Employee Data'!J3:J202)-MEDIAN('Employee Data'!J3:J202) -> 7770 | C7: Gap reveals right-skew from Directors
A8: Mean age | B8: =AVERAGE('Employee Data'!H3:H202) -> 30.535
A9: Mean tenure | B9: =AVERAGE('Employee Data'!I3:I202) -> 3.9555
A10: Most common performance rating (MODE) | B10: =MODE('Employee Data'!L3:L202) -> 3 | C10: → 3
A12: GENDER PAY GAP — OVERALL
A13: Mean salary — Female | B13: =AVERAGEIF('Employee Data'!G3:G202,"Female",'Employee Data'!J3:J202) -> 58555.556
A14: Mean salary — Male | B14: =AVERAGEIF('Employee Data'!G3:G202,"Male",'Employee Data'!J3:J202) -> 64119.469
A15: Mean gap % (M higher than F) | B15: =(AVERAGEIF('Employee Data'!G3:G202,"Male",'Employee Data'!J3:J202)-AVERAGEIF('Employee Data'!G3:G202,"Female",'Employee Data'!J3:J202))/AVERAGEIF('Employee Data'!G3:G202,"Male",'Employee Data'!J3:J202) -> 0.086774166 | C15: Format as % — ~8.7%
A17: GAP WITHIN JOB LEVELS (controls for level mix)
A18: Female mean salary — Junior | B18: =AVERAGEIFS('Employee Data'!J3:J202,'Employee Data'!G3:G202,"Female",'Employee Data'!D3:D202,"Junior") -> 32538.462
A19: Male mean salary — Junior | B19: =AVERAGEIFS('Employee Data'!J3:J202,'Employee Data'!G3:G202,"Male",'Employee Data'!D3:D202,"Junior") -> 36285.714
A20: Female mean salary — Mid | B20: =AVERAGEIFS('Employee Data'!J3:J202,'Employee Data'!G3:G202,"Female",'Employee Data'!D3:D202,"Mid") -> 50185.185
A21: Male mean salary — Mid | B21: =AVERAGEIFS('Employee Data'!J3:J202,'Employee Data'!G3:G202,"Male",'Employee Data'!D3:D202,"Mid") -> 54743.243
A22: Female mean salary — Senior | B22: =AVERAGEIFS('Employee Data'!J3:J202,'Employee Data'!G3:G202,"Female",'Employee Data'!D3:D202,"Senior") -> 78500
A23: Male mean salary — Senior | B23: =AVERAGEIFS('Employee Data'!J3:J202,'Employee Data'!G3:G202,"Male",'Employee Data'!D3:D202,"Senior") -> 83125
A24: Female mean salary — Lead | B24: =AVERAGEIFS('Employee Data'!J3:J202,'Employee Data'!G3:G202,"Female",'Employee Data'!D3:D202,"Lead") -> 100250
A25: Male mean salary — Lead | B25: =AVERAGEIFS('Employee Data'!J3:J202,'Employee Data'!G3:G202,"Male",'Employee Data'!D3:D202,"Lead") -> 115000
A26: Female mean salary — Director | B26: =AVERAGEIFS('Employee Data'!J3:J202,'Employee Data'!G3:G202,"Female",'Employee Data'!D3:D202,"Director") -> 141750
A27: Male mean salary — Director | B27: =AVERAGEIFS('Employee Data'!J3:J202,'Employee Data'!G3:G202,"Male",'Employee Data'!D3:D202,"Director") -> 140500

Sheet Ch6 — Spread & Outliers
A1: Chapter 6 — Spread & Outliers
A2: MIN, MAX, STDEV — identifying unusual values.
A4: RANGE & STANDARD DEVIATION
A5: Minimum salary | B5: =MIN('Employee Data'!J3:J202) -> 25000
A6: Maximum salary | B6: =MAX('Employee Data'!J3:J202) -> 149500
A7: Salary range (max–min) | B7: =MAX('Employee Data'!J3:J202)-MIN('Employee Data'!J3:J202) -> 124500
A8: Standard deviation of salary | B8: =STDEV('Employee Data'!J3:J202) -> 28818.216 | C8: Spread around the mean
A9: Coefficient of variation | B9: =STDEV('Employee Data'!J3:J202)/AVERAGE('Employee Data'!J3:J202) -> 0.46094395 | C9: Format as % — relative spread
A11: OUTLIER DETECTION (2-StDev rule)
A12: Upper outlier threshold (Mean+2×StDev) | B12: =AVERAGE('Employee Data'!J3:J202)+2*STDEV('Employee Data'!J3:J202) -> 120156.43
A13: Lower outlier threshold (Mean–2×StDev) | B13: =AVERAGE('Employee Data'!J3:J202)-2*STDEV('Employee Data'!J3:J202) -> 4883.5689
A14: Count of employees above upper threshold | B14: =COUNTIF('Employee Data'!J3:J202,">"&(AVERAGE('Employee Data'!J3:J202)+2*STDEV('Employee Data'!J3:J202))) -> 10
A16: SPREAD BY DEPARTMENT (array formulas)
A17: Salary StDev — Technology | B17: =STDEV(IF('Employee Data'!C3:C202="Technology",'Employee Data'!J3:J202)) -> 28818.216 | C17: Ctrl+Shift+Enter in older Excel (array formula)
A18: Salary StDev — Strategy | B18: =IFERROR(STDEV(IF('Employee Data'!C3:C202="Strategy",'Employee Data'!J3:J202)),"—") -> — | C18: Ctrl+Shift+Enter in older Excel (array formula)
A19: Salary StDev — Finance | B19: =IFERROR(STDEV(IF('Employee Data'!C3:C202="Finance",'Employee Data'!J3:J202)),"—") -> — | C19: Ctrl+Shift+Enter in older Excel (array formula)
A20: Salary StDev — Operations | B20: =IFERROR(STDEV(IF('Employee Data'!C3:C202="Operations",'Employee Data'!J3:J202)),"—") -> — | C20: Ctrl+Shift+Enter in older Excel (array formula)
A21: Salary StDev — People & Culture | B21: =IFERROR(STDEV(IF('Employee Data'!C3:C202="People & Culture",'Employee Data'!J3:J202)),"—") -> — | C21: Ctrl+Shift+Enter in older Excel (array formula)

Sheet Ch7 — Attrition
A1: Chapter 7 — Attrition Analysis
A2: Rates, profiles, and the cost of losing people.
A4: ATTRITION RATES
A5: Overall attrition rate | B5: =COUNTIF('Employee Data'!O3:O202,"Yes")/COUNTA('Employee Data'!B3:B202) -> 0.155 | C5: Format as % — ~15.5%
A6: Attrition rate — Technology | B6: =COUNTIFS('Employee Data'!C3:C202,"Technology",'Employee Data'!O3:O202,"Yes")/COUNTIF('Employee Data'!C3:C202,"Technology") -> 0.26 | C6: Format as % ← HIGHEST — nearly double average
A7: Attrition rate — Strategy | B7: =COUNTIFS('Employee Data'!C3:C202,"Strategy",'Employee Data'!O3:O202,"Yes")/COUNTIF('Employee Data'!C3:C202,"Strategy") -> 0.15 | C7: Format as %
A8: Attrition rate — Finance | B8: =COUNTIFS('Employee Data'!C3:C202,"Finance",'Employee Data'!O3:O202,"Yes")/COUNTIF('Employee Data'!C3:C202,"Finance") -> 0.13157895 | C8: Format as %
A9: Attrition rate — Operations | B9: =COUNTIFS('Employee Data'!C3:C202,"Operations",'Employee Data'!O3:O202,"Yes")/COUNTIF('Employee Data'!C3:C202,"Operations") -> 0.066666667 | C9: Format as % ← LOWEST — stable workforce
A10: Attrition rate — People & Culture | B10: =COUNTIFS('Employee Data'!C3:C202,"People & Culture",'Employee Data'!O3:O202,"Yes")/COUNTIF('Employee Data'!C3:C202,"People & Culture") -> 0.14814815 | C10: Format as %
A12: LEAVER vs STAYER PROFILE
A13: Leaver avg performance | B13: =AVERAGEIF('Employee Data'!O3:O202,"Yes",'Employee Data'!L3:L202) -> 4 | C13: → ~4.00 — losing HIGH performers
A14: Stayer avg performance | B14: =AVERAGEIF('Employee Data'!O3:O202,"No",'Employee Data'!L3:L202) -> 3.2485207 | C14: → ~3.25 — gap is the alarm signal
A15: Leaver avg tenure | B15: =AVERAGEIF('Employee Data'!O3:O202,"Yes",'Employee Data'!I3:I202) -> 3.5
A16: Tech leaver avg performance | B16: =AVERAGEIFS('Employee Data'!L3:L202,'Employee Data'!C3:C202,"Technology",'Employee Data'!O3:O202,"Yes") -> 4
A17: High performers (≥4) who left | B17: =COUNTIFS('Employee Data'!L3:L202,">=4",'Employee Data'!O3:O202,"Yes") -> 24
A19: COST OF ATTRITION
A20: Leavers' combined salary | B20: =SUMIF('Employee Data'!O3:O202,"Yes",'Employee Data'!J3:J202) -> 1908500
A21: Conservative replacement cost (×50%) | B21: =SUMIF('Employee Data'!O3:O202,"Yes",'Employee Data'!J3:J202)*0.5 -> 954250
A22: High-end replacement cost (×200%) | B22: =SUMIF('Employee Data'!O3:O202,"Yes",'Employee Data'!J3:J202)*2 -> 3817000

Sheet Ch7b — Correlations
A1: Chapter 7 — Correlation Analysis
A2: CORREL — relationships between workforce variables.
A4: CORREL FORMULAS
A5: Tenure vs Salary (overall) | B5: =CORREL('Employee Data'!I3:I202,'Employee Data'!J3:J202) -> 0.86255692 | C5: ~0.86 — strong, but see confounding note below
A6: Performance vs Salary (unconditional) | B6: =CORREL('Employee Data'!L3:L202,'Employee Data'!J3:J202) -> 0.26709813 | C6: ~0.27 — suppressed by level effect
A7: Training Hours vs Performance | B7: =CORREL('Employee Data'!M3:M202,'Employee Data'!L3:L202) -> 0.31332228 | C7: ~0.31 — weak-moderate; not causal
A8: Age vs Salary | B8: =CORREL('Employee Data'!H3:H202,'Employee Data'!J3:J202) -> 0.84163031
A10: WITHIN-LEVEL CORRELATIONS (array formulas, Ctrl+Shift+Enter)
A11: Tenure vs Salary — Senior only | B11: =CORREL(IF('Employee Data'!D3:D202="Senior",'Employee Data'!I3:I202),IF('Employee Data'!D3:D202="Senior",'Employee Data'!J3:J202)) -> 0.44482113 | C11: ~0.40 — much weaker than overall; the true within-level signal
A12: Perf vs Salary — Senior only | B12: =CORREL(IF('Employee Data'!D3:D202="Senior",'Employee Data'!L3:L202),IF('Employee Data'!D3:D202="Senior",'Employee Data'!J3:J202)) -> 0.61345821 | C12: ~0.61 — stronger; within level, performance matters more than across all levels
A14: INTERPRETATION GUIDE
A15: Coefficient Range | B15: Interpretation | C15: Unreal Consulting Example
A16: 0.80–1.00 | B16: Very strong positive | C16: Tenure–Salary overall (0.86) — confounded by level
A17: 0.50–0.79 | B17: Moderate–Strong | C17: Perf–Salary within levels (0.61–0.79)
A18: 0.30–0.49 | B18: Moderate | C18: Training–Performance (0.31)
A19: 0.10–0.29 | B19: Weak–Moderate | C19: Perf–Salary unconditional (0.27)
A20: -0.10–0.10 | B20: Negligible | C20: No meaningful linear relationship

Sheet Ch9 — Pivot Reference
A1: Chapter 9 — Expected Pivot Table Outputs
A2: Reference: what your Pivot Tables should show.
A4: Headcount & Attrition by Department
A5: Department | B5: Headcount | C5: Leavers | D5: Attrition % | E5: Note
A6: Technology | B6: 50 | C6: 13 | D6: 26.0% | E6: ← Highest — nearly double average
A7: Strategy | B7: 40 | C7: 6 | D7: 15.0%
A8: Finance | B8: 38 | C8: 5 | D8: 13.2%
A9: Operations | B9: 45 | C9: 3 | D9: 6.7% | E9: ← Lowest — stable workforce
A10: People & Culture | B10: 27 | C10: 4 | D10: 14.8%
A11: TOTAL | B11: 200 | C11: 31 | D11: 15.5% | E11: Overall company attrition
A14: Average Salary by Level & Gender (what your Pivot should show)
A15: Job Level | B15: Female | C15: Male | D15: Gap % | E15: Director note
A16: Junior | B16: £32,538 | C16: £36,286 | D16: 10.3%
A17: Mid | B17: £50,185 | C17: £54,743 | D17: 8.3%
A18: Senior | B18: £78,500 | C18: £83,125 | D18: 5.6%
A19: Lead | B19: £100,250 | C19: £115,000 | D19: 12.8% | E19: Small n (10F, 8M) — caveat
A20: Director | B20: — | C20: £139,500 | D20: n/a | E20: No female Directors in Finance or Operations — flag for HR
